Workbook

Sheet Original Data
A1: transaction_id | B1: product_id | C1: sale_date | D1: product_name | E1: brand | F1: store_id | G1: region | H1: quantity | I1: discount | J1: total | K1: payment_method | L1: sales_rep | M1: is_active
A2: 1 | B2: P001 | C2: 45031 | D2: Classic Crew-Neck Tee | E2: GAP | F2: S002 | G2: West | H2: 3 | I2: 0 | J2: 59.97 | K2: DEBIT CARD | M2: 0
A3: 2 | B3: P008 | C3: 45641 | D3: Denim Jacket | E3: GAP | F3: S007 | G3: Northeast | H3: 4 | I3: 0.1 | J3: 323.82 | K3: DEBIT CARD | L3: Maria S. | M3: TRUE
A4: 3 | B4: P015 | C4: 45492 | D4: NULL | E4: NULL | F4: S001 | G4: Northeast | H4: 5 | I4: 0 | J4: 224.75 | K4: CREDIT CARD | L4: Priya M. | M4: NULL
A5: 4 | B5: P008 | C5: 45577 | D5: NULL | E5: NULL | F5: S002 | G5: West | H5: 1 | I5: 0.2 | J5: 71.96 | K5: GIFT CARD | L5: Amy K. | M5: NULL
A6: 5 | B6: P006 | C6: 45631 | D6: Floral Midi Dress | E6: Banana Republic | F6: S004 | G6: South | H6: 4 | I6: 0 | J6: 319.8 | K6: APPLE PAY | M6: FALSE
A7: 6 | B7: P007 | C7: 45198 | D7: Running Leggings | E7: Athleta | F7: S006 | G7: West | H7: 4 | I7: 0.2 | J7: 207.84 | K7: DEBIT CARD | L7: Tom B. | M7: 1
A8: 7 | B8: P003 | C8: 45090 | D8: puffer jacket | E8: GAP | F8: S008 | H8: 1 | I8: 0 | J8: 129 | K8: APPLE PAY | L8: Lin W. | M8: TRUE
A9: 8 | B9: P004 | C9: 45227 | D9: Canvas Sneakers | E9: Old Navy | F9: S001 | G9: Northeast | H9: 5 | I9: 0.1 | J9: 224.78 | K9: CREDIT CARD | L9: David N. | M9: 0
A10: 9 | B10: P010 | C10: 45092 | D10: High-Rise Jeans | E10: GAP | F10: S002 | G10: West | H10: 5 | I10: 0.05 | J10: 332.26 | K10: CASH | L10: Lin W. | M10: 0
A11: 10 | B11: P008 | C11: 45424 | D11: Denim Jacket | E11: GAP | F11: S005 | G11: Southeast | H11: 1 | I11: 0.05 | J11: 85.45 | K11: CREDIT CARD | L11: James T. | M11: TRUE
A12: 11 | B12: P018 | C12: 45592 | D12: Rain Jacket | E12: Old Navy | F12: S004 | G12: South | H12: 2 | I12: 0.1 | J12: 153 | K12: APPLE PAY | L12: Priya M. | M12: 1
A13: 12 | B13: P002 | C13: 44999 | D13: Slim Chino Pants | E13: GAP | F13: S002 | G13: West | H13: 2 | I13: 0 | J13: 119.9 | K13: CASH | L13: Maria S. | M13: 1
A14: 13 | B14: P007 | C14: 45360 | D14: Running Leggings | E14: Athleta | F14: S007 | G14: Northeast | H14: 1 | I14: 0 | J14: 64.95 | K14: CASH | L14: Priya M. | M14: 1
A15: 14 | B15: P007 | C15: 45114 | D15: Running Leggings | E15: Athleta | F15: S004 | G15: South | H15: 2 | I15: 0.25 | J15: 97.43 | K15: GIFT CARD | L15: Lin W. | M15: 1
A16: 15 | B16: P003 | C16: 45419 | D16: puffer jacket | E16: GAP | F16: S001 | G16: Northeast | H16: 2 | I16: NA | J16: 258 | K16: GIFT CARD | L16: Priya M. | M16: TRUE
A17: 16 | B17: P005 | C17: 45520 | D17: Leather Belt | E17: Banana Republic | F17: S008 | H17: 2 | I17: 0.1 | J17: 62.98 | K17: CREDIT CARD | L17: Carlos R. | M17: 0
A18: 17 | B18: P006 | C18: 45049 | D18: Floral Midi Dress | E18: Banana Republic | F18: S002 | G18: West | H18: 1 | I18: 0 | J18: 79.95 | K18: GIFT CARD | L18: Carlos R. | M18: FALSE
A19: 18 | B19: P008 | C19: 45587 | D19: Denim Jacket | E19: GAP | F19: S006 | G19: West | H19: 3 | I19: 0 | J19: 269.85 | K19: APPLE PAY | L19: Lin W. | M19: TRUE
A20: 19 | B20: P008 | C20: 45483 | D20: Denim Jacket | E20: GAP | F20: S002 | G20: West | H20: 3 | I20: 0.1 | J20: 242.87 | K20: GIFT CARD | L20: Lin W. | M20: TRUE
A21: 20 | B21: P009 | C21: 45215 | D21: Wool Sweater | E21: Banana Republic | F21: S003 | G21: Midwest | H21: 1 | I21: 0 | J21: 74.95 | K21: CASH | L21: Lin W. | M21: 0
A22: 21 | B22: P009 | C22: 45579 | D22: Wool Sweater | E22: Banana Republic | F22: S007 | G22: Northeast | H22: 1 | I22: 0 | J22: 74.95 | K22: DEBIT CARD | L22: David N. | M22: 0
A23: 22 | B23: P012 | C23: 44969 | D23: Ankle Boots | E23: Banana Republic | F23: S001 | G23: Northeast | H23: 5 | I23: n/a | J23: 595 | K23: DEBIT CARD | L23: Priya M. | M23: FALSE
A24: 23 | B24: P020 | C24: 45349 | D24: Crossbody Bag | E24: Banana Republic | F24: S007 | G24: Northeast | H24: 2 | I24: 0.05 | J24: 113.9 | K24: DEBIT CARD | L24: Lin W. | M24: Yes
A25: 24 | B25: P013 | C25: 45398 | D25: Silk Scarf | E25: Intermix | F25: S002 | G25: West | H25: 1 | J25: 44.95 | K25: DEBIT CARD | M25: No
A26: 25 | B26: P017 | C26: 45194 | D26: Cargo Shorts | E26: Old Navy | F26: S006 | G26: West | H26: 4 | I26: 0.15 | J26: 135.83 | K26: CREDIT CARD | L26: Maria S. | M26: 1
A27: 26 | B27: P013 | C27: 45652 | D27: Silk Scarf | E27: Intermix | G27: NULL | H27: 5 | I27: 0.05 | J27: 213.51 | K27: CREDIT CARD | L27: Amy K. | M27: No
A28: 27 | B28: P020 | C28: 45243 | D28: Crossbody Bag | E28: Banana Republic | F28: S006 | G28: West | H28: 3 | I28: 0 | J28: 179.85 | K28: PAYPAL | L28: Amy K. | M28: Yes
A29: 28 | B29: P013 | C29: 45142 | D29: Silk Scarf | E29: Intermix | F29: S005 | G29: Southeast | H29: 5 | I29: 0 | J29: 224.75 | K29: CASH | L29: Amy K. | M29: No
A30: 29 | B30: P003 | C30: 45615 | D30: puffer jacket | E30: GAP | F30: S003 | G30: Midwest | H30: 3 | I30: 0.15 | J30: 328.95 | K30: DEBIT CARD | L30: James T. | M30: TRUE
A31: 30 | B31: P013 | C31: 45598 | D31: Silk Scarf | E31: Intermix | G31: NULL | H31: 4 | I31: 0.2 | J31: 143.84 | K31: DEBIT CARD | L31: Carlos R. | M31: No
A32: 31 | B32: P018 | C32: 45402 | D32: Rain Jacket | E32: Old Navy | F32: S001 | G32: Northeast | H32: 2 | I32: 0 | J32: 170 | K32: DEBIT CARD | L32: Tom B. | M32: 1
A33: 32 | B33: P006 | C33: 45579 | D33: Floral Midi Dress | E33: Banana Republic | F33: S008 | H33: 4 | I33: 0.25 | J33: 239.85 | K33: DEBIT CARD | L33: Amy K. | M33: FALSE
A34: 33 | B34: P005 | C34: 45083 | D34: Leather Belt | E34: Banana Republic | F34: S002 | G34: West | H34: 2 | I34: 0.05 | J34: 66.48 | K34: APPLE PAY | L34: Priya M. | M34: 0
A35: 34 | B35: P019 | C35: 45232 | D35: Slip-On Loafers | E35: GAP | F35: S001 | G35: Northeast | H35: 4 | I35: 0.25 | J35: 239.85 | K35: CASH | L35: Maria S. | M35: Yes
A36: 35 | B36: P016 | C36: 45622 | D36: Graphic Hoodie | E36: Old Navy | F36: S007 | G36: Northeast | H36: 1 | I36: 0.2 | J36: 39.96 | K36: APPLE PAY | L36: David N. | M36: 0
A37: 36 | B37: P014 | C37: 45193 | D37: Wrap Dress | E37: Intermix | F37: S002 | G37: West | H37: 2 | I37: 0.25 | J37: 134.93 | K37: CREDIT CARD | L37: Lin W. | M37: Yes
A38: 37 | B38: P001 | C38: 45592 | D38: NULL | E38: NULL | F38: S008 | H38: 5 | I38: 0 | J38: 99.95 | K38: DEBIT CARD | L38: David N. | M38: NULL
A39: 38 | B39: P019 | C39: 45098 | D39: Slip-On Loafers | E39: GAP | F39: S002 | G39: West | H39: 2 | I39: 0.25 | J39: 119.93 | K39: CASH | M39: Yes
A40: 39 | B40: P013 | C40: 45640 | D40: Silk Scarf | E40: Intermix | F40: S007 | G40: Northeast | H40: 2 | I40: 0 | J40: 89.9 | K40: CREDIT CARD | L40: Carlos R. | M40: No
...

Sheet Cleaned Data
A1: transaction_id | B1: product_id | C1: sale_date | D1: product_name | E1: brand | F1: store_id | G1: region | H1: quantity | I1: discount | J1: total | K1: payment_method | L1: sales_rep | M1: is_active
A2: 1 | B2: P001 | C2: 45031 | D2: Classic Crew-Neck Tee | E2: GAP | F2: S002 | G2: West | H2: 3 | I2: 0 | J2: 59.97 | K2: =PROPER('Original Data'!K2) -> Debit Card | M2: {=_xlfn.IFS(OR('Original Data'!M2=0,'Original Data'!M2="No",'Original Data'!M2=FALSE),"No",OR('Original Data'!M2=1,'Original Data'!M2="Yes",'Original Data'!M2=TRUE),"Yes")} -> No
A3: 2 | B3: P008 | C3: 45641 | D3: Denim Jacket | E3: GAP | F3: S007 | G3: Northeast | H3: 4 | I3: 0.1 | J3: 323.82 | K3: =PROPER('Original Data'!K3) -> Debit Card | L3: Maria S. | M3: {=_xlfn.IFS(OR('Original Data'!M3=0,'Original Data'!M3="No",'Original Data'!M3=FALSE),"No",OR('Original Data'!M3=1,'Original Data'!M3="Yes",'Original Data'!M3=TRUE),"Yes")} -> Yes
A4: 3 | B4: P015 | C4: 45492 | D4: =VLOOKUP(B4,'Original Data'!B:D,3,FALSE) -> NULL | E4: =_xlfn.XLOOKUP('Cleaned Data'!B823,'Original Data'!B:B,'Original Data'!E:E) -> Banana Republic | F4: S001 | G4: Northeast | H4: 5 | I4: 0 | J4: 224.75 | K4: =PROPER('Original Data'!K4) -> Credit Card | L4: Priya M. | M4: Unknown
A5: 4 | B5: P008 | C5: 45577 | D5: =VLOOKUP(B5,'Original Data'!B:D,3,FALSE) -> Denim Jacket | E5: =_xlfn.XLOOKUP('Cleaned Data'!B407,'Original Data'!B:B,'Original Data'!E:E) -> Athleta | F5: S002 | G5: West | H5: 1 | I5: 0.2 | J5: 71.96 | K5: =PROPER('Original Data'!K5) -> Gift Card | L5: Amy K. | M5: Unknown
A6: 5 | B6: P006 | C6: 45631 | D6: Floral Midi Dress | E6: Banana Republic | F6: S004 | G6: South | H6: 4 | I6: 0 | J6: 319.8 | K6: =PROPER('Original Data'!K6) -> Apple Pay | M6: {=_xlfn.IFS(OR('Original Data'!M6=0,'Original Data'!M6="No",'Original Data'!M6=FALSE),"No",OR('Original Data'!M6=1,'Original Data'!M6="Yes",'Original Data'!M6=TRUE),"Yes")} -> No
A7: 6 | B7: P007 | C7: 45198 | D7: Running Leggings | E7: Athleta | F7: S006 | G7: West | H7: 4 | I7: 0.2 | J7: 207.84 | K7: =PROPER('Original Data'!K7) -> Debit Card | L7: Tom B. | M7: {=_xlfn.IFS(OR('Original Data'!M7=0,'Original Data'!M7="No",'Original Data'!M7=FALSE),"No",OR('Original Data'!M7=1,'Original Data'!M7="Yes",'Original Data'!M7=TRUE),"Yes")} -> Yes
A8: 7 | B8: P003 | C8: 45090 | D8: Puffer Jacket | E8: GAP | F8: S008 | H8: 1 | I8: 0 | J8: 129 | K8: =PROPER('Original Data'!K8) -> Apple Pay | L8: Lin W. | M8: {=_xlfn.IFS(OR('Original Data'!M8=0,'Original Data'!M8="No",'Original Data'!M8=FALSE),"No",OR('Original Data'!M8=1,'Original Data'!M8="Yes",'Original Data'!M8=TRUE),"Yes")} -> Yes
A9: 8 | B9: P004 | C9: 45227 | D9: Canvas Sneakers | E9: Old Navy | F9: S001 | G9: Northeast | H9: 5 | I9: 0.1 | J9: 224.78 | K9: =PROPER('Original Data'!K9) -> Credit Card | L9: David N. | M9: {=_xlfn.IFS(OR('Original Data'!M9=0,'Original Data'!M9="No",'Original Data'!M9=FALSE),"No",OR('Original Data'!M9=1,'Original Data'!M9="Yes",'Original Data'!M9=TRUE),"Yes")} -> No
A10: 9 | B10: P010 | C10: 45092 | D10: High-Rise Jeans | E10: GAP | F10: S002 | G10: West | H10: 5 | I10: 0.05 | J10: 332.26 | K10: =PROPER('Original Data'!K10) -> Cash | L10: Lin W. | M10: {=_xlfn.IFS(OR('Original Data'!M10=0,'Original Data'!M10="No",'Original Data'!M10=FALSE),"No",OR('Original Data'!M10=1,'Original Data'!M10="Yes",'Original Data'!M10=TRUE),"Yes")} -> No
A11: 10 | B11: P008 | C11: 45424 | D11: Denim Jacket | E11: GAP | F11: S005 | G11: Southeast | H11: 1 | I11: 0.05 | J11: 85.45 | K11: =PROPER('Original Data'!K11) -> Credit Card | L11: James T. | M11: {=_xlfn.IFS(OR('Original Data'!M11=0,'Original Data'!M11="No",'Original Data'!M11=FALSE),"No",OR('Original Data'!M11=1,'Original Data'!M11="Yes",'Original Data'!M11=TRUE),"Yes")} -> Yes
A12: 11 | B12: P018 | C12: 45592 | D12: Rain Jacket | E12: Old Navy | F12: S004 | G12: South | H12: 2 | I12: 0.1 | J12: 153 | K12: =PROPER('Original Data'!K12) -> Apple Pay | L12: Priya M. | M12: {=_xlfn.IFS(OR('Original Data'!M12=0,'Original Data'!M12="No",'Original Data'!M12=FALSE),"No",OR('Original Data'!M12=1,'Original Data'!M12="Yes",'Original Data'!M12=TRUE),"Yes")} -> Yes
A13: 12 | B13: P002 | C13: 44999 | D13: Slim Chino Pants | E13: GAP | F13: S002 | G13: West | H13: 2 | I13: 0 | J13: 119.9 | K13: =PROPER('Original Data'!K13) -> Cash | L13: Maria S. | M13: {=_xlfn.IFS(OR('Original Data'!M13=0,'Original Data'!M13="No",'Original Data'!M13=FALSE),"No",OR('Original Data'!M13=1,'Original Data'!M13="Yes",'Original Data'!M13=TRUE),"Yes")} -> Yes
A14: 13 | B14: P007 | C14: 45360 | D14: Running Leggings | E14: Athleta | F14: S007 | G14: Northeast | H14: 1 | I14: 0 | J14: 64.95 | K14: =PROPER('Original Data'!K14) -> Cash | L14: Priya M. | M14: {=_xlfn.IFS(OR('Original Data'!M14=0,'Original Data'!M14="No",'Original Data'!M14=FALSE),"No",OR('Original Data'!M14=1,'Original Data'!M14="Yes",'Original Data'!M14=TRUE),"Yes")} -> Yes
A15: 14 | B15: P007 | C15: 45114 | D15: Running Leggings | E15: Athleta | F15: S004 | G15: South | H15: 2 | I15: 0.25 | J15: 97.43 | K15: =PROPER('Original Data'!K15) -> Gift Card | L15: Lin W. | M15: {=_xlfn.IFS(OR('Original Data'!M15=0,'Original Data'!M15="No",'Original Data'!M15=FALSE),"No",OR('Original Data'!M15=1,'Original Data'!M15="Yes",'Original Data'!M15=TRUE),"Yes")} -> Yes
A16: 15 | B16: P003 | C16: 45419 | D16: Puffer Jacket | E16: GAP | F16: S001 | G16: Northeast | H16: 2 | I16: 0 | J16: 258 | K16: =PROPER('Original Data'!K16) -> Gift Card | L16: Priya M. | M16: {=_xlfn.IFS(OR('Original Data'!M16=0,'Original Data'!M16="No",'Original Data'!M16=FALSE),"No",OR('Original Data'!M16=1,'Original Data'!M16="Yes",'Original Data'!M16=TRUE),"Yes")} -> Yes
A17: 16 | B17: P005 | C17: 45520 | D17: Leather Belt | E17: Banana Republic | F17: S008 | H17: 2 | I17: 0.1 | J17: 62.98 | K17: =PROPER('Original Data'!K17) -> Credit Card | L17: Carlos R. | M17: {=_xlfn.IFS(OR('Original Data'!M17=0,'Original Data'!M17="No",'Original Data'!M17=FALSE),"No",OR('Original Data'!M17=1,'Original Data'!M17="Yes",'Original Data'!M17=TRUE),"Yes")} -> No
A18: 17 | B18: P006 | C18: 45049 | D18: Floral Midi Dress | E18: Banana Republic | F18: S002 | G18: West | H18: 1 | I18: 0 | J18: 79.95 | K18: =PROPER('Original Data'!K18) -> Gift Card | L18: Carlos R. | M18: {=_xlfn.IFS(OR('Original Data'!M18=0,'Original Data'!M18="No",'Original Data'!M18=FALSE),"No",OR('Original Data'!M18=1,'Original Data'!M18="Yes",'Original Data'!M18=TRUE),"Yes")} -> No
A19: 18 | B19: P008 | C19: 45587 | D19: Denim Jacket | E19: GAP | F19: S006 | G19: West | H19: 3 | I19: 0 | J19: 269.85 | K19: =PROPER('Original Data'!K19) -> Apple Pay | L19: Lin W. | M19: {=_xlfn.IFS(OR('Original Data'!M19=0,'Original Data'!M19="No",'Original Data'!M19=FALSE),"No",OR('Original Data'!M19=1,'Original Data'!M19="Yes",'Original Data'!M19=TRUE),"Yes")} -> Yes
A20: 19 | B20: P008 | C20: 45483 | D20: Denim Jacket | E20: GAP | F20: S002 | G20: West | H20: 3 | I20: 0.1 | J20: 242.87 | K20: =PROPER('Original Data'!K20) -> Gift Card | L20: Lin W. | M20: {=_xlfn.IFS(OR('Original Data'!M20=0,'Original Data'!M20="No",'Original Data'!M20=FALSE),"No",OR('Original Data'!M20=1,'Original Data'!M20="Yes",'Original Data'!M20=TRUE),"Yes")} -> Yes
A21: 20 | B21: P009 | C21: 45215 | D21: Wool Sweater | E21: Banana Republic | F21: S003 | G21: Midwest | H21: 1 | I21: 0 | J21: 74.95 | K21: =PROPER('Original Data'!K21) -> Cash | L21: Lin W. | M21: {=_xlfn.IFS(OR('Original Data'!M21=0,'Original Data'!M21="No",'Original Data'!M21=FALSE),"No",OR('Original Data'!M21=1,'Original Data'!M21="Yes",'Original Data'!M21=TRUE),"Yes")} -> No
A22: 21 | B22: P009 | C22: 45579 | D22: Wool Sweater | E22: Banana Republic | F22: S007 | G22: Northeast | H22: 1 | I22: 0 | J22: 74.95 | K22: =PROPER('Original Data'!K22) -> Debit Card | L22: David N. | M22: {=_xlfn.IFS(OR('Original Data'!M22=0,'Original Data'!M22="No",'Original Data'!M22=FALSE),"No",OR('Original Data'!M22=1,'Original Data'!M22="Yes",'Original Data'!M22=TRUE),"Yes")} -> No
A23: 22 | B23: P012 | C23: 44969 | D23: Ankle Boots | E23: Banana Republic | F23: S001 | G23: Northeast | H23: 5 | I23: 0 | J23: 595 | K23: =PROPER('Original Data'!K23) -> Debit Card | L23: Priya M. | M23: {=_xlfn.IFS(OR('Original Data'!M23=0,'Original Data'!M23="No",'Original Data'!M23=FALSE),"No",OR('Original Data'!M23=1,'Original Data'!M23="Yes",'Original Data'!M23=TRUE),"Yes")} -> No
A24: 23 | B24: P020 | C24: 45349 | D24: Crossbody Bag | E24: Banana Republic | F24: S007 | G24: Northeast | H24: 2 | I24: 0.05 | J24: 113.9 | K24: =PROPER('Original Data'!K24) -> Debit Card | L24: Lin W. | M24: {=_xlfn.IFS(OR('Original Data'!M24=0,'Original Data'!M24="No",'Original Data'!M24=FALSE),"No",OR('Original Data'!M24=1,'Original Data'!M24="Yes",'Original Data'!M24=TRUE),"Yes")} -> Yes
A25: 24 | B25: P013 | C25: 45398 | D25: Silk Scarf | E25: Intermix | F25: S002 | G25: West | H25: 1 | J25: 44.95 | K25: =PROPER('Original Data'!K25) -> Debit Card | M25: {=_xlfn.IFS(OR('Original Data'!M25=0,'Original Data'!M25="No",'Original Data'!M25=FALSE),"No",OR('Original Data'!M25=1,'Original Data'!M25="Yes",'Original Data'!M25=TRUE),"Yes")} -> No
A26: 25 | B26: P017 | C26: 45194 | D26: Cargo Shorts | E26: Old Navy | F26: S006 | G26: West | H26: 4 | I26: 0.15 | J26: 135.83 | K26: =PROPER('Original Data'!K26) -> Credit Card | L26: Maria S. | M26: {=_xlfn.IFS(OR('Original Data'!M26=0,'Original Data'!M26="No",'Original Data'!M26=FALSE),"No",OR('Original Data'!M26=1,'Original Data'!M26="Yes",'Original Data'!M26=TRUE),"Yes")} -> Yes
A27: 26 | B27: P013 | C27: 45652 | D27: Silk Scarf | E27: Intermix | G27: NULL | H27: 5 | I27: 0.05 | J27: 213.51 | K27: =PROPER('Original Data'!K27) -> Credit Card | L27: Amy K. | M27: {=_xlfn.IFS(OR('Original Data'!M27=0,'Original Data'!M27="No",'Original Data'!M27=FALSE),"No",OR('Original Data'!M27=1,'Original Data'!M27="Yes",'Original Data'!M27=TRUE),"Yes")} -> No
A28: 27 | B28: P020 | C28: 45243 | D28: Crossbody Bag | E28: Banana Republic | F28: S006 | G28: West | H28: 3 | I28: 0 | J28: 179.85 | K28: PayPal | L28: Amy K. | M28: {=_xlfn.IFS(OR('Original Data'!M28=0,'Original Data'!M28="No",'Original Data'!M28=FALSE),"No",OR('Original Data'!M28=1,'Original Data'!M28="Yes",'Original Data'!M28=TRUE),"Yes")} -> Yes
A29: 28 | B29: P013 | C29: 45142 | D29: Silk Scarf | E29: Intermix | F29: S005 | G29: Southeast | H29: 5 | I29: 0 | J29: 224.75 | K29: =PROPER('Original Data'!K29) -> Cash | L29: Amy K. | M29: {=_xlfn.IFS(OR('Original Data'!M29=0,'Original Data'!M29="No",'Original Data'!M29=FALSE),"No",OR('Original Data'!M29=1,'Original Data'!M29="Yes",'Original Data'!M29=TRUE),"Yes")} -> No
A30: 29 | B30: P003 | C30: 45615 | D30: Puffer Jacket | E30: GAP | F30: S003 | G30: Midwest | H30: 3 | I30: 0.15 | J30: 328.95 | K30: =PROPER('Original Data'!K30) -> Debit Card | L30: James T. | M30: {=_xlfn.IFS(OR('Original Data'!M30=0,'Original Data'!M30="No",'Original Data'!M30=FALSE),"No",OR('Original Data'!M30=1,'Original Data'!M30="Yes",'Original Data'!M30=TRUE),"Yes")} -> Yes
A31: 30 | B31: P013 | C31: 45598 | D31: Silk Scarf | E31: Intermix | G31: NULL | H31: 4 | I31: 0.2 | J31: 143.84 | K31: =PROPER('Original Data'!K31) -> Debit Card | L31: Carlos R. | M31: {=_xlfn.IFS(OR('Original Data'!M31=0,'Original Data'!M31="No",'Original Data'!M31=FALSE),"No",OR('Original Data'!M31=1,'Original Data'!M31="Yes",'Original Data'!M31=TRUE),"Yes")} -> No
A32: 31 | B32: P018 | C32: 45402 | D32: Rain Jacket | E32: Old Navy | F32: S001 | G32: Northeast | H32: 2 | I32: 0 | J32: 170 | K32: =PROPER('Original Data'!K32) -> Debit Card | L32: Tom B. | M32: {=_xlfn.IFS(OR('Original Data'!M32=0,'Original Data'!M32="No",'Original Data'!M32=FALSE),"No",OR('Original Data'!M32=1,'Original Data'!M32="Yes",'Original Data'!M32=TRUE),"Yes")} -> Yes
A33: 32 | B33: P006 | C33: 45579 | D33: Floral Midi Dress | E33: Banana Republic | F33: S008 | H33: 4 | I33: 0.25 | J33: 239.85 | K33: =PROPER('Original Data'!K33) -> Debit Card | L33: Amy K. | M33: {=_xlfn.IFS(OR('Original Data'!M33=0,'Original Data'!M33="No",'Original Data'!M33=FALSE),"No",OR('Original Data'!M33=1,'Original Data'!M33="Yes",'Original Data'!M33=TRUE),"Yes")} -> No
A34: 33 | B34: P005 | C34: 45083 | D34: Leather Belt | E34: Banana Republic | F34: S002 | G34: West | H34: 2 | I34: 0.05 | J34: 66.48 | K34: =PROPER('Original Data'!K34) -> Apple Pay | L34: Priya M. | M34: {=_xlfn.IFS(OR('Original Data'!M34=0,'Original Data'!M34="No",'Original Data'!M34=FALSE),"No",OR('Original Data'!M34=1,'Original Data'!M34="Yes",'Original Data'!M34=TRUE),"Yes")} -> No
A35: 34 | B35: P019 | C35: 45232 | D35: Slip-On Loafers | E35: GAP | F35: S001 | G35: Northeast | H35: 4 | I35: 0.25 | J35: 239.85 | K35: =PROPER('Original Data'!K35) -> Cash | L35: Maria S. | M35: {=_xlfn.IFS(OR('Original Data'!M35=0,'Original Data'!M35="No",'Original Data'!M35=FALSE),"No",OR('Original Data'!M35=1,'Original Data'!M35="Yes",'Original Data'!M35=TRUE),"Yes")} -> Yes
A36: 35 | B36: P016 | C36: 45622 | D36: Graphic Hoodie | E36: Old Navy | F36: S007 | G36: Northeast | H36: 1 | I36: 0.2 | J36: 39.96 | K36: =PROPER('Original Data'!K36) -> Apple Pay | L36: David N. | M36: {=_xlfn.IFS(OR('Original Data'!M36=0,'Original Data'!M36="No",'Original Data'!M36=FALSE),"No",OR('Original Data'!M36=1,'Original Data'!M36="Yes",'Original Data'!M36=TRUE),"Yes")} -> No
A37: 36 | B37: P014 | C37: 45193 | D37: Wrap Dress | E37: Intermix | F37: S002 | G37: West | H37: 2 | I37: 0.25 | J37: 134.93 | K37: =PROPER('Original Data'!K37) -> Credit Card | L37: Lin W. | M37: {=_xlfn.IFS(OR('Original Data'!M37=0,'Original Data'!M37="No",'Original Data'!M37=FALSE),"No",OR('Original Data'!M37=1,'Original Data'!M37="Yes",'Original Data'!M37=TRUE),"Yes")} -> Yes
A38: 37 | B38: P001 | C38: 45592 | D38: Classic Crew-Neck Tee | E38: GAP | F38: S008 | H38: 5 | I38: 0 | J38: 99.95 | K38: =PROPER('Original Data'!K38) -> Debit Card | L38: David N. | M38: Unknown
A39: 38 | B39: P019 | C39: 45098 | D39: Slip-On Loafers | E39: GAP | F39: S002 | G39: West | H39: 2 | I39: 0.25 | J39: 119.93 | K39: =PROPER('Original Data'!K39) -> Cash | M39: {=_xlfn.IFS(OR('Original Data'!M39=0,'Original Data'!M39="No",'Original Data'!M39=FALSE),"No",OR('Original Data'!M39=1,'Original Data'!M39="Yes",'Original Data'!M39=TRUE),"Yes")} -> Yes
A40: 39 | B40: P013 | C40: 45640 | D40: Silk Scarf | E40: Intermix | F40: S007 | G40: Northeast | H40: 2 | I40: 0 | J40: 89.9 | K40: =PROPER('Original Data'!K40) -> Credit Card | L40: Carlos R. | M40: {=_xlfn.IFS(OR('Original Data'!M40=0,'Original Data'!M40="No",'Original Data'!M40=FALSE),"No",OR('Original Data'!M40=1,'Original Data'!M40="Yes",'Original Data'!M40=TRUE),"Yes")} -> No
...
